Workbook

Sheet Line Plan
A1: LINE PLAN UPLOAD
A3: LINE CODE | B3: Rumiya_Line | C3: Fill in the production line code before uploading.
A4: HALL NAME | B4: Hall B | C4: Hall/area name (if auto-creating the line). | D4: Hall/area name (if auto-creating the line).
A5: DATE | B5: 2026-03-26 | C5: Work date — YYYY-MM-DD format. | D5: Work date — YYYY-MM-DD format. | E5: Work date — YYYY-MM-DD format.
A6: PRODUCT CODE | B6: KN754 | C6: Style/product code. | D6: Style/product code. | E6: Style/product code. | F6: Style/product code.
A7: PRODUCT NAME | B7: KATESPADE | C7: Full product name. | D7: Full product name. | E7: Full product name. | F7: Full product name. | G7: Full product name.
A8: BUYER NAME | C8: Buyer / brand name. Optional. | D8: Buyer / brand name. Optional. | E8: Buyer / brand name. Optional. | F8: Buyer / brand name. Optional. | G8: Buyer / brand name. Optional. | H8: Buyer / brand name. Optional.
A9: PLAN MONTH | B9: 2026-04 | C9: Plan month (e.g. 2026-04). | D9: Plan month (e.g. 2026-04). | E9: Plan month (e.g. 2026-04). | F9: Plan month (e.g. 2026-04). | G9: Plan month (e.g. 2026-04). | H9: Plan month (e.g. 2026-04). | I9: Plan month (e.g. 2026-04).
A10: TARGET UNITS | B10: 350 | C10: Daily target for this line. Required. | D10: Daily target for this line. Required. | E10: Daily target for this line. Required. | F10: Daily target for this line. Required. | G10: Daily target for this line. Required. | H10: Daily target for this line. Required. | I10: Daily target for this line. Required. | J10: Daily target for this line. Required.
A11: CO PRODUCT CODE | C11: Optional. | D11: Optional. | E11: Optional. | F11: Optional. | G11: Optional. | H11: Optional. | I11: Optional. | J11: Optional.
A12: CO TARGET | C12: Optional. | D12: Optional. | E12: Optional. | F12: Optional. | G12: Optional. | H12: Optional. | I12: Optional. | J12: Optional.
A13: LINE LEADER | B13: Rumiya | C13: Fill before uploading. | D13: Fill before uploading. | E13: Fill before uploading. | F13: Fill before uploading. | G13: Fill before uploading. | H13: Fill before uploading. | I13: Fill before uploading. | J13: Fill before uploading.
A15: GROUP | B15: OSM | C15: WORKSTATION | D15: OPERATION CODE | E15: OPERATION NAME | F15: PROCESS TIME (s) | G15: CYCLE TIME (s) | H15: SAH | I15: EMP CODE (auto) | J15: SELECT EMPLOYEE ▼
A16: G1 | B16: OSM1 | C16: W1 | E16: Heating | F16: 10 | G16: =SUMIF($C$16:$C$501,C16,$F$16:$F$501) | H16: =F16/3600 | I16: =IFERROR(INDEX(Lists!$C:$C,MATCH(J16,Lists!$D:$D,0)),"") | J16: A. JAMEELA
A17: G1 | B17: OSM1 | C17: W1 | E17: board with lining attatching & 1st primer | F17: 25.5 | G17: =SUMIF($C$16:$C$501,C17,$F$16:$F$501) | H17: =F17/3600 | I17: =IFERROR(INDEX(Lists!$C:$C,MATCH(J17,Lists!$D:$D,0)),"") | J17: =J16
A18: G1 | B18: OSM1 | C18: W1 | E18: die process | F18: 25.5 | G18: =SUMIF($C$16:$C$501,C18,$F$16:$F$501) | H18: =F18/3600 | I18: =IFERROR(INDEX(Lists!$C:$C,MATCH(J18,Lists!$D:$D,0)),"") | J18: =J16
A19: G1 | B19: OSM1 | C19: W2 | E19: Heating | F19: 10 | G19: =SUMIF($C$16:$C$501,C19,$F$16:$F$501) | H19: =F19/3600 | I19: =IFERROR(INDEX(Lists!$C:$C,MATCH(J19,Lists!$D:$D,0)),"") | J19: USHA
A20: G1 | B20: OSM1 | C20: W2 | E20: board with lining attatching & 1st primer | F20: 25.5 | G20: =SUMIF($C$16:$C$501,C20,$F$16:$F$501) | H20: =F20/3600 | I20: =IFERROR(INDEX(Lists!$C:$C,MATCH(J20,Lists!$D:$D,0)),"") | J20: =J19
A21: G1 | B21: OSM1 | C21: W2 | E21: die process | F21: 25.5 | G21: =SUMIF($C$16:$C$501,C21,$F$16:$F$501) | H21: =F21/3600 | I21: =IFERROR(INDEX(Lists!$C:$C,MATCH(J21,Lists!$D:$D,0)),"") | J21: =J19
A22: G1 | B22: OSM1 | C22: W3 | E22: Pasting on patti (5*1 Nos) | F22: 15 | G22: =SUMIF($C$16:$C$501,C22,$F$16:$F$501) | H22: =F22/3600 | I22: =IFERROR(INDEX(Lists!$C:$C,MATCH(J22,Lists!$D:$D,0)),"") | J22: USHA
A23: G1 | B23: OSM1 | C23: W3 | E23: Attaching step patti (4*1 Nos) | F23: 16 | G23: =SUMIF($C$16:$C$501,C23,$F$16:$F$501) | H23: =F23/3600 | I23: =IFERROR(INDEX(Lists!$C:$C,MATCH(J23,Lists!$D:$D,0)),"") | J23: =J22
A24: G1 | B24: OSM1 | C24: W3 | E24: Pasting on stamp & pkt (1-Nos) | F24: 12 | G24: =SUMIF($C$16:$C$501,C24,$F$16:$F$501) | H24: =F24/3600 | I24: =IFERROR(INDEX(Lists!$C:$C,MATCH(J24,Lists!$D:$D,0)),"") | J24: =J22
A25: G1 | B25: OSM1 | C25: W3 | E25: Attaching stamp with cc pkt | F25: 8 | G25: =SUMIF($C$16:$C$501,C25,$F$16:$F$501) | H25: =F25/3600 | I25: =IFERROR(INDEX(Lists!$C:$C,MATCH(J25,Lists!$D:$D,0)),"") | J25: =J22
A26: G1 | B26: OSM1 | C26: W3 | E26: Pasting on patti (4*1 Nos) | F26: 12 | G26: =SUMIF($C$16:$C$501,C26,$F$16:$F$501) | H26: =F26/3600 | I26: =IFERROR(INDEX(Lists!$C:$C,MATCH(J26,Lists!$D:$D,0)),"") | J26: =J22
A27: G1 | B27: OSM1 | C27: W3 | E27: Attaching step patti (3*1 Nos) | F27: 12 | G27: =SUMIF($C$16:$C$501,C27,$F$16:$F$501) | H27: =F27/3600 | I27: =IFERROR(INDEX(Lists!$C:$C,MATCH(J27,Lists!$D:$D,0)),"") | J27: =J22
A28: G1 | B28: OSM1 | C28: W4 | E28: Stitching the lining (4*1 Nos) | F28: 20 | G28: =SUMIF($C$16:$C$501,C28,$F$16:$F$501) | H28: =F28/3600 | I28: =IFERROR(INDEX(Lists!$C:$C,MATCH(J28,Lists!$D:$D,0)),"") | J28: JAYALAKSHMI
A29: G1 | B29: OSM1 | C29: W4 | E29: Stitching closing lining (1*1 Nos) | F29: 12 | G29: =SUMIF($C$16:$C$501,C29,$F$16:$F$501) | H29: =F29/3600 | I29: =IFERROR(INDEX(Lists!$C:$C,MATCH(J29,Lists!$D:$D,0)),"") | J29: =J28
A30: G1 | B30: OSM1 | C30: W4 | E30: Stitching the lining (3*1 Nos) | F30: 13.5 | G30: =SUMIF($C$16:$C$501,C30,$F$16:$F$501) | H30: =F30/3600 | I30: =IFERROR(INDEX(Lists!$C:$C,MATCH(J30,Lists!$D:$D,0)),"") | J30: =J28
A31: G1 | B31: OSM1 | C31: W4 | E31: Stitching the lining (1*1 Nos) | F31: 5 | G31: =SUMIF($C$16:$C$501,C31,$F$16:$F$501) | H31: =F31/3600 | I31: =IFERROR(INDEX(Lists!$C:$C,MATCH(J31,Lists!$D:$D,0)),"") | J31: =J28
A32: G1 | B32: OSM1 | C32: W5 | E32: Recutting of cc pkt (1:2) 1-Nos | F32: 8 | G32: =SUMIF($C$16:$C$501,C32,$F$16:$F$501) | H32: =F32/3600 | I32: =IFERROR(INDEX(Lists!$C:$C,MATCH(J32,Lists!$D:$D,0)),"") | J32: ASLAM
A33: G1 | B33: OSM1 | C33: W5 | E33: Recutting of cc pkt (1:2) 1-Nos | F33: 8 | G33: =SUMIF($C$16:$C$501,C33,$F$16:$F$501) | H33: =F33/3600 | I33: =IFERROR(INDEX(Lists!$C:$C,MATCH(J33,Lists!$D:$D,0)),"") | J33: =J32
A34: G1 | B34: OSM1 | C34: W5 | E34: Recutting of center stay (1:2) | F34: 9 | G34: =SUMIF($C$16:$C$501,C34,$F$16:$F$501) | H34: =F34/3600 | I34: =IFERROR(INDEX(Lists!$C:$C,MATCH(J34,Lists!$D:$D,0)),"") | J34: =J32
A35: G1 | B35: OSM1 | C35: W5 | E35: Recutting of center stay (1:2) | F35: 9 | G35: =SUMIF($C$16:$C$501,C35,$F$16:$F$501) | H35: =F35/3600 | I35: =IFERROR(INDEX(Lists!$C:$C,MATCH(J35,Lists!$D:$D,0)),"") | J35: =J32
A36: G1 | B36: OSM1 | C36: W6 | E36: Pasting on lining (1-Nos) | F36: 10 | G36: =SUMIF($C$16:$C$501,C36,$F$16:$F$501) | H36: =F36/3600 | I36: =IFERROR(INDEX(Lists!$C:$C,MATCH(J36,Lists!$D:$D,0)),"") | J36: VENDA
A37: G1 | B37: OSM1 | C37: W6 | E37: Attaching with lining closing(1-Nos) | F37: 7 | G37: =SUMIF($C$16:$C$501,C37,$F$16:$F$501) | H37: =F37/3600 | I37: =IFERROR(INDEX(Lists!$C:$C,MATCH(J37,Lists!$D:$D,0)),"") | J37: =J36
A38: G1 | B38: OSM1 | C38: W6 | E38: Pasting cover lining and cc pkt (1-Nos) | F38: 14 | G38: =SUMIF($C$16:$C$501,C38,$F$16:$F$501) | H38: =F38/3600 | I38: =IFERROR(INDEX(Lists!$C:$C,MATCH(J38,Lists!$D:$D,0)),"") | J38: =J36
A39: G1 | B39: OSM1 | C39: W6 | E39: Attaching cover lining and cc pkt (1-Nos) | F39: 10 | G39: =SUMIF($C$16:$C$501,C39,$F$16:$F$501) | H39: =F39/3600 | I39: =IFERROR(INDEX(Lists!$C:$C,MATCH(J39,Lists!$D:$D,0)),"") | J39: =J36
A40: G1 | B40: OSM1 | C40: W6 | E40: Pasting lining | F40: 6 | G40: =SUMIF($C$16:$C$501,C40,$F$16:$F$501) | H40: =F40/3600 | I40: =IFERROR(INDEX(Lists!$C:$C,MATCH(J40,Lists!$D:$D,0)),"") | J40: =J36
A41: G1 | B41: OSM1 | C41: W6 | E41: Lining folding | F41: 6 | G41: =SUMIF($C$16:$C$501,C41,$F$16:$F$501) | H41: =F41/3600 | I41: =IFERROR(INDEX(Lists!$C:$C,MATCH(J41,Lists!$D:$D,0)),"") | J41: =J36
A42: G1 | B42: OSM1 | C42: W6 | E42: Pasting on lining & beeding | F42: 8 | G42: =SUMIF($C$16:$C$501,C42,$F$16:$F$501) | H42: =F42/3600 | I42: =IFERROR(INDEX(Lists!$C:$C,MATCH(J42,Lists!$D:$D,0)),"") | J42: =J36
...

Sheet Lists
A1: OPERATION CODE | B1: OPERATION NAME | C1: EMPLOYEE CODE | D1: EMPLOYEE NAME
C2: LPDS95761 | D2: A FATHIMA
C3: LPDS95657 | D3: A JOTHI
C4: LPD11959 | D4: A MEENAKSHI
C5: LPD02946 | D5: A. ALEMELU
C6: LPD07479 | D6: A. CHANMA
C7: LPD10419 | D7: A. FARHANA BEGAM
C8: LPD07739 | D8: A. JAMEELA
C9: LPD00059 | D9: A. NOORUN
C10: LPD03353 | D10: A. RAFI
C11: LPD07294 | D11: A. RAMEZA
C12: LPD00601 | D12: A. SADIKHA
C13: LPD09996 | D13: A. YASEEN BEE
... C225: LPD11520 | D225: ZAREENA
