Workbook

Sheet Line Plan
A1: LINE PLAN UPLOAD
A3: LINE CODE | B3: Rumiya_Line | C3: Production line code. Auto-created if not in system.
A4: HALL NAME | B4: Hall B | C4: Hall/area name.
A5: DATE | B5: 2026-03-26 | C5: Work date — YYYY-MM-DD format.
A6: PRODUCT CODE | B6: KN754 | C6: Style/product code. Auto-created if new.
A7: PRODUCT NAME | B7: KATESPADE | C7: Full product name.
A8: BUYER NAME | C8: Buyer / brand name. Optional.
A9: PLAN MONTH | B9: 2026-04 | C9: Plan month (e.g. 2026-04). Optional.
A10: TARGET UNITS | B10: 350 | C10: Daily target for this line. Required.
A11: CO PRODUCT CODE | C11: Optional — changeover product code.
A12: CO TARGET | C12: Optional — changeover target units.
A13: LINE LEADER | B13: Rumiya | C13: Line leader name.
A15: GROUP | B15: OSM | C15: WORKSTATION ▼ | D15: OP CODE (auto) | E15: SELECT OPERATION ▼ | F15: PROCESS TIME (s) | G15: CYCLE TIME (s) | H15: SAH | I15: EMP CODE (auto) | J15: SELECT EMPLOYEE ▼
A16: G1 | B16: OSM1 | C16: W1 | D16: =IF(E16="","",IF(ISNUMBER(FIND("|",E16)),TRIM(LEFT(E16,FIND("|",E16)-1)),IF(ISNUMBER(MATCH(E16,Config!$C$1:$C$211,0)),E16,IFERROR(INDEX(Config!$C$1:$C$211,MATCH(E16,Config!$D$1:$D$211,0)),"")))) -> OP-0014 | E16: Heating | F16: 10 | G16: =SUMIF($C$16:$C$241,C16,$F$16:$F$241) -> 61 | H16: =F16/3600 -> 0.0027777778 | I16: =IF(J16="","",IF(ISNUMBER(FIND("|",J16)),TRIM(LEFT(J16,FIND("|",J16)-1)),IF(ISNUMBER(MATCH(J16,Config!$F$1:$F$224,0)),J16,IFERROR(INDEX(Config!$F$1:$F$224,MATCH(J16,Config!$G$1:$G$224,0)),"")))) -> LPD07739 | J16: A. JAMEELA
A17: G1 | B17: OSM1 | C17: W1 | D17: =IF(E17="","",IF(ISNUMBER(FIND("|",E17)),TRIM(LEFT(E17,FIND("|",E17)-1)),IF(ISNUMBER(MATCH(E17,Config!$C$1:$C$211,0)),E17,IFERROR(INDEX(Config!$C$1:$C$211,MATCH(E17,Config!$D$1:$D$211,0)),"")))) -> OP-0015 | E17: board with lining attatching & 1st primer | F17: 25.5 | G17: =SUMIF($C$16:$C$241,C17,$F$16:$F$241) -> 61 | H17: =F17/3600 -> 0.0070833333 | I17: =IF(J17="","",IF(ISNUMBER(FIND("|",J17)),TRIM(LEFT(J17,FIND("|",J17)-1)),IF(ISNUMBER(MATCH(J17,Config!$F$1:$F$224,0)),J17,IFERROR(INDEX(Config!$F$1:$F$224,MATCH(J17,Config!$G$1:$G$224,0)),"")))) -> LPD07739 | J17: =IFERROR(INDEX($J$16:J16,MATCH(C17,$C$16:C16,0)),"") -> A. JAMEELA
A18: G1 | B18: OSM1 | C18: W1 | D18: =IF(E18="","",IF(ISNUMBER(FIND("|",E18)),TRIM(LEFT(E18,FIND("|",E18)-1)),IF(ISNUMBER(MATCH(E18,Config!$C$1:$C$211,0)),E18,IFERROR(INDEX(Config!$C$1:$C$211,MATCH(E18,Config!$D$1:$D$211,0)),"")))) -> OP-0016 | E18: die process | F18: 25.5 | G18: =SUMIF($C$16:$C$241,C18,$F$16:$F$241) -> 61 | H18: =F18/3600 -> 0.0070833333 | I18: =IF(J18="","",IF(ISNUMBER(FIND("|",J18)),TRIM(LEFT(J18,FIND("|",J18)-1)),IF(ISNUMBER(MATCH(J18,Config!$F$1:$F$224,0)),J18,IFERROR(INDEX(Config!$F$1:$F$224,MATCH(J18,Config!$G$1:$G$224,0)),"")))) -> LPD07739 | J18: =IFERROR(INDEX($J$16:J17,MATCH(C18,$C$16:C17,0)),"") -> A. JAMEELA
A19: G1 | B19: OSM1 | C19: W2 | D19: =IF(E19="","",IF(ISNUMBER(FIND("|",E19)),TRIM(LEFT(E19,FIND("|",E19)-1)),IF(ISNUMBER(MATCH(E19,Config!$C$1:$C$211,0)),E19,IFERROR(INDEX(Config!$C$1:$C$211,MATCH(E19,Config!$D$1:$D$211,0)),"")))) -> OP-0014 | E19: Heating | F19: 10 | G19: =SUMIF($C$16:$C$241,C19,$F$16:$F$241) -> 61 | H19: =F19/3600 -> 0.0027777778 | I19: =IF(J19="","",IF(ISNUMBER(FIND("|",J19)),TRIM(LEFT(J19,FIND("|",J19)-1)),IF(ISNUMBER(MATCH(J19,Config!$F$1:$F$224,0)),J19,IFERROR(INDEX(Config!$F$1:$F$224,MATCH(J19,Config!$G$1:$G$224,0)),"")))) -> LPD11454 | J19: USHA
A20: G1 | B20: OSM1 | C20: W2 | D20: =IF(E20="","",IF(ISNUMBER(FIND("|",E20)),TRIM(LEFT(E20,FIND("|",E20)-1)),IF(ISNUMBER(MATCH(E20,Config!$C$1:$C$211,0)),E20,IFERROR(INDEX(Config!$C$1:$C$211,MATCH(E20,Config!$D$1:$D$211,0)),"")))) -> OP-0015 | E20: board with lining attatching & 1st primer | F20: 25.5 | G20: =SUMIF($C$16:$C$241,C20,$F$16:$F$241) -> 61 | H20: =F20/3600 -> 0.0070833333 | I20: =IF(J20="","",IF(ISNUMBER(FIND("|",J20)),TRIM(LEFT(J20,FIND("|",J20)-1)),IF(ISNUMBER(MATCH(J20,Config!$F$1:$F$224,0)),J20,IFERROR(INDEX(Config!$F$1:$F$224,MATCH(J20,Config!$G$1:$G$224,0)),"")))) -> LPD11454 | J20: =IFERROR(INDEX($J$16:J19,MATCH(C20,$C$16:C19,0)),"") -> USHA
A21: G1 | B21: OSM1 | C21: W2 | D21: =IF(E21="","",IF(ISNUMBER(FIND("|",E21)),TRIM(LEFT(E21,FIND("|",E21)-1)),IF(ISNUMBER(MATCH(E21,Config!$C$1:$C$211,0)),E21,IFERROR(INDEX(Config!$C$1:$C$211,MATCH(E21,Config!$D$1:$D$211,0)),"")))) -> OP-0016 | E21: die process | F21: 25.5 | G21: =SUMIF($C$16:$C$241,C21,$F$16:$F$241) -> 61 | H21: =F21/3600 -> 0.0070833333 | I21: =IF(J21="","",IF(ISNUMBER(FIND("|",J21)),TRIM(LEFT(J21,FIND("|",J21)-1)),IF(ISNUMBER(MATCH(J21,Config!$F$1:$F$224,0)),J21,IFERROR(INDEX(Config!$F$1:$F$224,MATCH(J21,Config!$G$1:$G$224,0)),"")))) -> LPD11454 | J21: =IFERROR(INDEX($J$16:J20,MATCH(C21,$C$16:C20,0)),"") -> USHA
A22: G1 | B22: OSM1 | C22: W3 | D22: =IF(E22="","",IF(ISNUMBER(FIND("|",E22)),TRIM(LEFT(E22,FIND("|",E22)-1)),IF(ISNUMBER(MATCH(E22,Config!$C$1:$C$211,0)),E22,IFERROR(INDEX(Config!$C$1:$C$211,MATCH(E22,Config!$D$1:$D$211,0)),"")))) -> OP-0017 | E22: Pasting on patti (5*1 Nos) | F22: 15 | G22: =SUMIF($C$16:$C$241,C22,$F$16:$F$241) -> 75 | H22: =F22/3600 -> 0.0041666667 | I22: =IF(J22="","",IF(ISNUMBER(FIND("|",J22)),TRIM(LEFT(J22,FIND("|",J22)-1)),IF(ISNUMBER(MATCH(J22,Config!$F$1:$F$224,0)),J22,IFERROR(INDEX(Config!$F$1:$F$224,MATCH(J22,Config!$G$1:$G$224,0)),"")))) -> LPD11454 | J22: USHA
A23: G1 | B23: OSM1 | C23: W3 | D23: =IF(E23="","",IF(ISNUMBER(FIND("|",E23)),TRIM(LEFT(E23,FIND("|",E23)-1)),IF(ISNUMBER(MATCH(E23,Config!$C$1:$C$211,0)),E23,IFERROR(INDEX(Config!$C$1:$C$211,MATCH(E23,Config!$D$1:$D$211,0)),"")))) -> OP-0018 | E23: Attaching step patti (4*1 Nos) | F23: 16 | G23: =SUMIF($C$16:$C$241,C23,$F$16:$F$241) -> 75 | H23: =F23/3600 -> 0.0044444444 | I23: =IF(J23="","",IF(ISNUMBER(FIND("|",J23)),TRIM(LEFT(J23,FIND("|",J23)-1)),IF(ISNUMBER(MATCH(J23,Config!$F$1:$F$224,0)),J23,IFERROR(INDEX(Config!$F$1:$F$224,MATCH(J23,Config!$G$1:$G$224,0)),"")))) -> LPD11454 | J23: =IFERROR(INDEX($J$16:J22,MATCH(C23,$C$16:C22,0)),"") -> USHA
A24: G1 | B24: OSM1 | C24: W3 | D24: =IF(E24="","",IF(ISNUMBER(FIND("|",E24)),TRIM(LEFT(E24,FIND("|",E24)-1)),IF(ISNUMBER(MATCH(E24,Config!$C$1:$C$211,0)),E24,IFERROR(INDEX(Config!$C$1:$C$211,MATCH(E24,Config!$D$1:$D$211,0)),"")))) -> OP-0019 | E24: Pasting on stamp & pkt (1-Nos) | F24: 12 | G24: =SUMIF($C$16:$C$241,C24,$F$16:$F$241) -> 75 | H24: =F24/3600 -> 0.0033333333 | I24: =IF(J24="","",IF(ISNUMBER(FIND("|",J24)),TRIM(LEFT(J24,FIND("|",J24)-1)),IF(ISNUMBER(MATCH(J24,Config!$F$1:$F$224,0)),J24,IFERROR(INDEX(Config!$F$1:$F$224,MATCH(J24,Config!$G$1:$G$224,0)),"")))) -> LPD11454 | J24: =IFERROR(INDEX($J$16:J23,MATCH(C24,$C$16:C23,0)),"") -> USHA
A25: G1 | B25: OSM1 | C25: W3 | D25: =IF(E25="","",IF(ISNUMBER(FIND("|",E25)),TRIM(LEFT(E25,FIND("|",E25)-1)),IF(ISNUMBER(MATCH(E25,Config!$C$1:$C$211,0)),E25,IFERROR(INDEX(Config!$C$1:$C$211,MATCH(E25,Config!$D$1:$D$211,0)),"")))) -> OP-0020 | E25: Attaching stamp with cc pkt | F25: 8 | G25: =SUMIF($C$16:$C$241,C25,$F$16:$F$241) -> 75 | H25: =F25/3600 -> 0.0022222222 | I25: =IF(J25="","",IF(ISNUMBER(FIND("|",J25)),TRIM(LEFT(J25,FIND("|",J25)-1)),IF(ISNUMBER(MATCH(J25,Config!$F$1:$F$224,0)),J25,IFERROR(INDEX(Config!$F$1:$F$224,MATCH(J25,Config!$G$1:$G$224,0)),"")))) -> LPD11454 | J25: =IFERROR(INDEX($J$16:J24,MATCH(C25,$C$16:C24,0)),"") -> USHA
A26: G1 | B26: OSM1 | C26: W3 | D26: =IF(E26="","",IF(ISNUMBER(FIND("|",E26)),TRIM(LEFT(E26,FIND("|",E26)-1)),IF(ISNUMBER(MATCH(E26,Config!$C$1:$C$211,0)),E26,IFERROR(INDEX(Config!$C$1:$C$211,MATCH(E26,Config!$D$1:$D$211,0)),"")))) -> OP-0021 | E26: Pasting on patti (4*1 Nos) | F26: 12 | G26: =SUMIF($C$16:$C$241,C26,$F$16:$F$241) -> 75 | H26: =F26/3600 -> 0.0033333333 | I26: =IF(J26="","",IF(ISNUMBER(FIND("|",J26)),TRIM(LEFT(J26,FIND("|",J26)-1)),IF(ISNUMBER(MATCH(J26,Config!$F$1:$F$224,0)),J26,IFERROR(INDEX(Config!$F$1:$F$224,MATCH(J26,Config!$G$1:$G$224,0)),"")))) -> LPD11454 | J26: =IFERROR(INDEX($J$16:J25,MATCH(C26,$C$16:C25,0)),"") -> USHA
A27: G1 | B27: OSM1 | C27: W3 | D27: =IF(E27="","",IF(ISNUMBER(FIND("|",E27)),TRIM(LEFT(E27,FIND("|",E27)-1)),IF(ISNUMBER(MATCH(E27,Config!$C$1:$C$211,0)),E27,IFERROR(INDEX(Config!$C$1:$C$211,MATCH(E27,Config!$D$1:$D$211,0)),"")))) -> OP-0022 | E27: Attaching step patti (3*1 Nos) | F27: 12 | G27: =SUMIF($C$16:$C$241,C27,$F$16:$F$241) -> 75 | H27: =F27/3600 -> 0.0033333333 | I27: =IF(J27="","",IF(ISNUMBER(FIND("|",J27)),TRIM(LEFT(J27,FIND("|",J27)-1)),IF(ISNUMBER(MATCH(J27,Config!$F$1:$F$224,0)),J27,IFERROR(INDEX(Config!$F$1:$F$224,MATCH(J27,Config!$G$1:$G$224,0)),"")))) -> LPD11454 | J27: =IFERROR(INDEX($J$16:J26,MATCH(C27,$C$16:C26,0)),"") -> USHA
A28: G1 | B28: OSM1 | C28: W4 | D28: =IF(E28="","",IF(ISNUMBER(FIND("|",E28)),TRIM(LEFT(E28,FIND("|",E28)-1)),IF(ISNUMBER(MATCH(E28,Config!$C$1:$C$211,0)),E28,IFERROR(INDEX(Config!$C$1:$C$211,MATCH(E28,Config!$D$1:$D$211,0)),"")))) -> OP-0023 | E28: Stitching the lining (4*1 Nos) | F28: 20 | G28: =SUMIF($C$16:$C$241,C28,$F$16:$F$241) -> 50.5 | H28: =F28/3600 -> 0.0055555556 | I28: =IF(J28="","",IF(ISNUMBER(FIND("|",J28)),TRIM(LEFT(J28,FIND("|",J28)-1)),IF(ISNUMBER(MATCH(J28,Config!$F$1:$F$224,0)),J28,IFERROR(INDEX(Config!$F$1:$F$224,MATCH(J28,Config!$G$1:$G$224,0)),"")))) -> LPDS95750 | J28: JAYALAKSHMI
A29: G1 | B29: OSM1 | C29: W4 | D29: =IF(E29="","",IF(ISNUMBER(FIND("|",E29)),TRIM(LEFT(E29,FIND("|",E29)-1)),IF(ISNUMBER(MATCH(E29,Config!$C$1:$C$211,0)),E29,IFERROR(INDEX(Config!$C$1:$C$211,MATCH(E29,Config!$D$1:$D$211,0)),"")))) -> OP-0024 | E29: Stitching closing lining (1*1 Nos) | F29: 12 | G29: =SUMIF($C$16:$C$241,C29,$F$16:$F$241) -> 50.5 | H29: =F29/3600 -> 0.0033333333 | I29: =IF(J29="","",IF(ISNUMBER(FIND("|",J29)),TRIM(LEFT(J29,FIND("|",J29)-1)),IF(ISNUMBER(MATCH(J29,Config!$F$1:$F$224,0)),J29,IFERROR(INDEX(Config!$F$1:$F$224,MATCH(J29,Config!$G$1:$G$224,0)),"")))) -> LPDS95750 | J29: =IFERROR(INDEX($J$16:J28,MATCH(C29,$C$16:C28,0)),"") -> JAYALAKSHMI
A30: G1 | B30: OSM1 | C30: W4 | D30: =IF(E30="","",IF(ISNUMBER(FIND("|",E30)),TRIM(LEFT(E30,FIND("|",E30)-1)),IF(ISNUMBER(MATCH(E30,Config!$C$1:$C$211,0)),E30,IFERROR(INDEX(Config!$C$1:$C$211,MATCH(E30,Config!$D$1:$D$211,0)),"")))) -> OP-0025 | E30: Stitching the lining (3*1 Nos) | F30: 13.5 | G30: =SUMIF($C$16:$C$241,C30,$F$16:$F$241) -> 50.5 | H30: =F30/3600 -> 0.00375 | I30: =IF(J30="","",IF(ISNUMBER(FIND("|",J30)),TRIM(LEFT(J30,FIND("|",J30)-1)),IF(ISNUMBER(MATCH(J30,Config!$F$1:$F$224,0)),J30,IFERROR(INDEX(Config!$F$1:$F$224,MATCH(J30,Config!$G$1:$G$224,0)),"")))) -> LPDS95750 | J30: =IFERROR(INDEX($J$16:J29,MATCH(C30,$C$16:C29,0)),"") -> JAYALAKSHMI
A31: G1 | B31: OSM1 | C31: W4 | D31: =IF(E31="","",IF(ISNUMBER(FIND("|",E31)),TRIM(LEFT(E31,FIND("|",E31)-1)),IF(ISNUMBER(MATCH(E31,Config!$C$1:$C$211,0)),E31,IFERROR(INDEX(Config!$C$1:$C$211,MATCH(E31,Config!$D$1:$D$211,0)),"")))) -> OP-0026 | E31: Stitching the lining (1*1 Nos) | F31: 5 | G31: =SUMIF($C$16:$C$241,C31,$F$16:$F$241) -> 50.5 | H31: =F31/3600 -> 0.0013888889 | I31: =IF(J31="","",IF(ISNUMBER(FIND("|",J31)),TRIM(LEFT(J31,FIND("|",J31)-1)),IF(ISNUMBER(MATCH(J31,Config!$F$1:$F$224,0)),J31,IFERROR(INDEX(Config!$F$1:$F$224,MATCH(J31,Config!$G$1:$G$224,0)),"")))) -> LPDS95750 | J31: =IFERROR(INDEX($J$16:J30,MATCH(C31,$C$16:C30,0)),"") -> JAYALAKSHMI
A32: G1 | B32: OSM1 | C32: W5 | D32: =IF(E32="","",IF(ISNUMBER(FIND("|",E32)),TRIM(LEFT(E32,FIND("|",E32)-1)),IF(ISNUMBER(MATCH(E32,Config!$C$1:$C$211,0)),E32,IFERROR(INDEX(Config!$C$1:$C$211,MATCH(E32,Config!$D$1:$D$211,0)),"")))) -> OP-0027 | E32: Recutting of cc pkt (1:2) 1-Nos | F32: 8 | G32: =SUMIF($C$16:$C$241,C32,$F$16:$F$241) -> 34 | H32: =F32/3600 -> 0.0022222222 | I32: =IF(J32="","",IF(ISNUMBER(FIND("|",J32)),TRIM(LEFT(J32,FIND("|",J32)-1)),IF(ISNUMBER(MATCH(J32,Config!$F$1:$F$224,0)),J32,IFERROR(INDEX(Config!$F$1:$F$224,MATCH(J32,Config!$G$1:$G$224,0)),"")))) -> LPDS95789 | J32: ASLAM
A33: G1 | B33: OSM1 | C33: W5 | D33: =IF(E33="","",IF(ISNUMBER(FIND("|",E33)),TRIM(LEFT(E33,FIND("|",E33)-1)),IF(ISNUMBER(MATCH(E33,Config!$C$1:$C$211,0)),E33,IFERROR(INDEX(Config!$C$1:$C$211,MATCH(E33,Config!$D$1:$D$211,0)),"")))) -> OP-0027 | E33: Recutting of cc pkt (1:2) 1-Nos | F33: 8 | G33: =SUMIF($C$16:$C$241,C33,$F$16:$F$241) -> 34 | H33: =F33/3600 -> 0.0022222222 | I33: =IF(J33="","",IF(ISNUMBER(FIND("|",J33)),TRIM(LEFT(J33,FIND("|",J33)-1)),IF(ISNUMBER(MATCH(J33,Config!$F$1:$F$224,0)),J33,IFERROR(INDEX(Config!$F$1:$F$224,MATCH(J33,Config!$G$1:$G$224,0)),"")))) -> LPDS95789 | J33: =IFERROR(INDEX($J$16:J32,MATCH(C33,$C$16:C32,0)),"") -> ASLAM
A34: G1 | B34: OSM1 | C34: W5 | D34: =IF(E34="","",IF(ISNUMBER(FIND("|",E34)),TRIM(LEFT(E34,FIND("|",E34)-1)),IF(ISNUMBER(MATCH(E34,Config!$C$1:$C$211,0)),E34,IFERROR(INDEX(Config!$C$1:$C$211,MATCH(E34,Config!$D$1:$D$211,0)),"")))) -> OP-0028 | E34: Recutting of center stay (1:2) | F34: 9 | G34: =SUMIF($C$16:$C$241,C34,$F$16:$F$241) -> 34 | H34: =F34/3600 -> 0.0025 | I34: =IF(J34="","",IF(ISNUMBER(FIND("|",J34)),TRIM(LEFT(J34,FIND("|",J34)-1)),IF(ISNUMBER(MATCH(J34,Config!$F$1:$F$224,0)),J34,IFERROR(INDEX(Config!$F$1:$F$224,MATCH(J34,Config!$G$1:$G$224,0)),"")))) -> LPDS95789 | J34: =IFERROR(INDEX($J$16:J33,MATCH(C34,$C$16:C33,0)),"") -> ASLAM
A35: G1 | B35: OSM1 | C35: W5 | D35: =IF(E35="","",IF(ISNUMBER(FIND("|",E35)),TRIM(LEFT(E35,FIND("|",E35)-1)),IF(ISNUMBER(MATCH(E35,Config!$C$1:$C$211,0)),E35,IFERROR(INDEX(Config!$C$1:$C$211,MATCH(E35,Config!$D$1:$D$211,0)),"")))) -> OP-0028 | E35: Recutting of center stay (1:2) | F35: 9 | G35: =SUMIF($C$16:$C$241,C35,$F$16:$F$241) -> 34 | H35: =F35/3600 -> 0.0025 | I35: =IF(J35="","",IF(ISNUMBER(FIND("|",J35)),TRIM(LEFT(J35,FIND("|",J35)-1)),IF(ISNUMBER(MATCH(J35,Config!$F$1:$F$224,0)),J35,IFERROR(INDEX(Config!$F$1:$F$224,MATCH(J35,Config!$G$1:$G$224,0)),"")))) -> LPDS95789 | J35: =IFERROR(INDEX($J$16:J34,MATCH(C35,$C$16:C34,0)),"") -> ASLAM
A36: G1 | B36: OSM1 | C36: W6 | D36: =IF(E36="","",IF(ISNUMBER(FIND("|",E36)),TRIM(LEFT(E36,FIND("|",E36)-1)),IF(ISNUMBER(MATCH(E36,Config!$C$1:$C$211,0)),E36,IFERROR(INDEX(Config!$C$1:$C$211,MATCH(E36,Config!$D$1:$D$211,0)),"")))) -> OP-0029 | E36: Pasting on lining (1-Nos) | F36: 10 | G36: =SUMIF($C$16:$C$241,C36,$F$16:$F$241) -> 69 | H36: =F36/3600 -> 0.0027777778 | I36: =IF(J36="","",IF(ISNUMBER(FIND("|",J36)),TRIM(LEFT(J36,FIND("|",J36)-1)),IF(ISNUMBER(MATCH(J36,Config!$F$1:$F$224,0)),J36,IFERROR(INDEX(Config!$F$1:$F$224,MATCH(J36,Config!$G$1:$G$224,0)),"")))) -> LPD05998 | J36: VENDA
A37: G1 | B37: OSM1 | C37: W6 | D37: =IF(E37="","",IF(ISNUMBER(FIND("|",E37)),TRIM(LEFT(E37,FIND("|",E37)-1)),IF(ISNUMBER(MATCH(E37,Config!$C$1:$C$211,0)),E37,IFERROR(INDEX(Config!$C$1:$C$211,MATCH(E37,Config!$D$1:$D$211,0)),"")))) -> OP-0030 | E37: Attaching with lining closing(1-Nos) | F37: 7 | G37: =SUMIF($C$16:$C$241,C37,$F$16:$F$241) -> 69 | H37: =F37/3600 -> 0.0019444444 | I37: =IF(J37="","",IF(ISNUMBER(FIND("|",J37)),TRIM(LEFT(J37,FIND("|",J37)-1)),IF(ISNUMBER(MATCH(J37,Config!$F$1:$F$224,0)),J37,IFERROR(INDEX(Config!$F$1:$F$224,MATCH(J37,Config!$G$1:$G$224,0)),"")))) -> LPD05998 | J37: =IFERROR(INDEX($J$16:J36,MATCH(C37,$C$16:C36,0)),"") -> VENDA
A38: G1 | B38: OSM1 | C38: W6 | D38: =IF(E38="","",IF(ISNUMBER(FIND("|",E38)),TRIM(LEFT(E38,FIND("|",E38)-1)),IF(ISNUMBER(MATCH(E38,Config!$C$1:$C$211,0)),E38,IFERROR(INDEX(Config!$C$1:$C$211,MATCH(E38,Config!$D$1:$D$211,0)),"")))) -> OP-0031 | E38: Pasting cover lining and cc pkt (1-Nos) | F38: 14 | G38: =SUMIF($C$16:$C$241,C38,$F$16:$F$241) -> 69 | H38: =F38/3600 -> 0.0038888889 | I38: =IF(J38="","",IF(ISNUMBER(FIND("|",J38)),TRIM(LEFT(J38,FIND("|",J38)-1)),IF(ISNUMBER(MATCH(J38,Config!$F$1:$F$224,0)),J38,IFERROR(INDEX(Config!$F$1:$F$224,MATCH(J38,Config!$G$1:$G$224,0)),"")))) -> LPD05998 | J38: =IFERROR(INDEX($J$16:J37,MATCH(C38,$C$16:C37,0)),"") -> VENDA
A39: G1 | B39: OSM1 | C39: W6 | D39: =IF(E39="","",IF(ISNUMBER(FIND("|",E39)),TRIM(LEFT(E39,FIND("|",E39)-1)),IF(ISNUMBER(MATCH(E39,Config!$C$1:$C$211,0)),E39,IFERROR(INDEX(Config!$C$1:$C$211,MATCH(E39,Config!$D$1:$D$211,0)),"")))) -> OP-0032 | E39: Attaching cover lining and cc pkt (1-Nos) | F39: 10 | G39: =SUMIF($C$16:$C$241,C39,$F$16:$F$241) -> 69 | H39: =F39/3600 -> 0.0027777778 | I39: =IF(J39="","",IF(ISNUMBER(FIND("|",J39)),TRIM(LEFT(J39,FIND("|",J39)-1)),IF(ISNUMBER(MATCH(J39,Config!$F$1:$F$224,0)),J39,IFERROR(INDEX(Config!$F$1:$F$224,MATCH(J39,Config!$G$1:$G$224,0)),"")))) -> LPD05998 | J39: =IFERROR(INDEX($J$16:J38,MATCH(C39,$C$16:C38,0)),"") -> VENDA
A40: G1 | B40: OSM1 | C40: W6 | D40: =IF(E40="","",IF(ISNUMBER(FIND("|",E40)),TRIM(LEFT(E40,FIND("|",E40)-1)),IF(ISNUMBER(MATCH(E40,Config!$C$1:$C$211,0)),E40,IFERROR(INDEX(Config!$C$1:$C$211,MATCH(E40,Config!$D$1:$D$211,0)),"")))) -> OP-0033 | E40: Pasting lining | F40: 6 | G40: =SUMIF($C$16:$C$241,C40,$F$16:$F$241) -> 69 | H40: =F40/3600 -> 0.0016666667 | I40: =IF(J40="","",IF(ISNUMBER(FIND("|",J40)),TRIM(LEFT(J40,FIND("|",J40)-1)),IF(ISNUMBER(MATCH(J40,Config!$F$1:$F$224,0)),J40,IFERROR(INDEX(Config!$F$1:$F$224,MATCH(J40,Config!$G$1:$G$224,0)),"")))) -> LPD05998 | J40: =IFERROR(INDEX($J$16:J39,MATCH(C40,$C$16:C39,0)),"") -> VENDA
A41: G1 | B41: OSM1 | C41: W6 | D41: =IF(E41="","",IF(ISNUMBER(FIND("|",E41)),TRIM(LEFT(E41,FIND("|",E41)-1)),IF(ISNUMBER(MATCH(E41,Config!$C$1:$C$211,0)),E41,IFERROR(INDEX(Config!$C$1:$C$211,MATCH(E41,Config!$D$1:$D$211,0)),"")))) -> OP-0034 | E41: Lining folding | F41: 6 | G41: =SUMIF($C$16:$C$241,C41,$F$16:$F$241) -> 69 | H41: =F41/3600 -> 0.0016666667 | I41: =IF(J41="","",IF(ISNUMBER(FIND("|",J41)),TRIM(LEFT(J41,FIND("|",J41)-1)),IF(ISNUMBER(MATCH(J41,Config!$F$1:$F$224,0)),J41,IFERROR(INDEX(Config!$F$1:$F$224,MATCH(J41,Config!$G$1:$G$224,0)),"")))) -> LPD05998 | J41: =IFERROR(INDEX($J$16:J40,MATCH(C41,$C$16:C40,0)),"") -> VENDA
A42: G1 | B42: OSM1 | C42: W6 | D42: =IF(E42="","",IF(ISNUMBER(FIND("|",E42)),TRIM(LEFT(E42,FIND("|",E42)-1)),IF(ISNUMBER(MATCH(E42,Config!$C$1:$C$211,0)),E42,IFERROR(INDEX(Config!$C$1:$C$211,MATCH(E42,Config!$D$1:$D$211,0)),"")))) -> OP-0035 | E42: Pasting on lining & beeding | F42: 8 | G42: =SUMIF($C$16:$C$241,C42,$F$16:$F$241) -> 69 | H42: =F42/3600 -> 0.0022222222 | I42: =IF(J42="","",IF(ISNUMBER(FIND("|",J42)),TRIM(LEFT(J42,FIND("|",J42)-1)),IF(ISNUMBER(MATCH(J42,Config!$F$1:$F$224,0)),J42,IFERROR(INDEX(Config!$F$1:$F$224,MATCH(J42,Config!$G$1:$G$224,0)),"")))) -> LPD05998 | J42: =IFERROR(INDEX($J$16:J41,MATCH(C42,$C$16:C41,0)),"") -> VENDA
...

Sheet Config
A1: WS01 | B1: G1 | C1: OP-0001 | D1: TOP PASTING | E1: OP-0001 | TOP PASTING | F1: LPDS95761 | G1: A FATHIMA | H1: LPDS95761 | A FATHIMA
A2: WS02 | B2: G2 | C2: OP-0002 | D2: KIMLON PASTING | E2: OP-0002 | KIMLON PASTING | F2: LPDS95657 | G2: A JOTHI | H2: LPDS95657 | A JOTHI
A3: WS03 | B3: G3 | C3: OP-0003 | D3: ATTACHING TOP & KIMLON | E3: OP-0003 | ATTACHING TOP & KIMLON | F3: LPD11959 | G3: A MEENAKSHI | H3: LPD11959 | A MEENAKSHI
A4: WS04 | B4: G4 | C4: OP-0004 | D4: GUSSET STITCHING -2NOS | E4: OP-0004 | GUSSET STITCHING -2NOS | F4: LPD02946 | G4: A. ALEMELU | H4: LPD02946 | A. ALEMELU
A5: WS05 | B5: G5 | C5: OP-0005 | D5: GUSSET LAMPING -2NOS | E5: OP-0005 | GUSSET LAMPING -2NOS | F5: LPD07479 | G5: A. CHANMA | H5: LPD07479 | A. CHANMA
A6: WS06 | B6: G6 | C6: OP-0006 | D6: GUSSET SHAPING | E6: OP-0006 | GUSSET SHAPING | F6: LPD10419 | G6: A. FARHANA BEGAM | H6: LPD10419 | A. FARHANA BEGAM
A7: WS07 | B7: G7 | C7: OP-0007 | D7: PATTI PROMOTOR | E7: OP-0007 | PATTI PROMOTOR | F7: LPD07739 | G7: A. JAMEELA | H7: LPD07739 | A. JAMEELA
A8: WS08 | B8: G8 | C8: OP-0008 | D8: PATTI PRIMER 1 | E8: OP-0008 | PATTI PRIMER 1 | F8: LPD00059 | G8: A. NOORUN | H8: LPD00059 | A. NOORUN
A9: WS09 | B9: G9 | C9: OP-0009 | D9: PATTI DYE | E9: OP-0009 | PATTI DYE | F9: LPD03353 | G9: A. RAFI | H9: LPD03353 | A. RAFI
A10: WS10 | B10: G10 | C10: OP-0010 | D10: PATTI PRIMER 2 | E10: OP-0010 | PATTI PRIMER 2 | F10: LPD07294 | G10: A. RAMEZA | H10: LPD07294 | A. RAMEZA
A11: WS11 | B11: G11 | C11: OP-0011 | D11: CLEANING | E11: OP-0011 | CLEANING | F11: LPD00601 | G11: A. SADIKHA | H11: LPD00601 | A. SADIKHA
A12: WS12 | B12: G12 | C12: OP-0012 | D12: CLEANING | E12: OP-0012 | CLEANING | F12: LPD09996 | G12: A. YASEEN BEE | H12: LPD09996 | A. YASEEN BEE
... A50: WS50 | B50: G50 | C50: OP-0050 | D50: Decorative Stitching of Anchor Bit | E50: OP-0050 | Decorative Stitching of Anchor Bit | F50: LPD11988 | G50: F GULZAR | H50: LPD11988 | F GULZAR
A51: WS51 | C51: OP-0051 | D51: Pasting top leather & facing leather | E51: OP-0051 | Pasting top leather & facing leather | F51: LPD07960 | G51: F. ZAINATHBEE | H51: LPD07960 | F. ZAINATHBEE
A52: WS52 | C52: OP-0052 | D52: Attaching top & facing leather | E52: OP-0052 | Attaching top & facing leather | F52: LPDS95161 | G52: FOUSIYA | H52: LPDS95161 | FOUSIYA
A53: WS53 | C53: OP-0053 | D53: Lamping | E53: OP-0053 | Lamping | F53: LPD04519 | G53: G. MANIMALA | H53: LPD04519 | G. MANIMALA
A54: WS54 | C54: OP-0054 | D54: Lamping of anchor tab bit | E54: OP-0054 | Lamping of anchor tab bit | F54: LPD03298 | G54: G. PADMINI | H54: LPD03298 | G. PADMINI
A55: WS55 | C55: OP-0055 | D55: Pressing | E55: OP-0055 | Pressing | F55: LPD01253 | G55: G. SARASWATHI | H55: LPD01253 | G. SARASWATHI
A56: WS56 | C56: OP-0056 | D56: Primer | E56: OP-0056 | Primer | F56: LPD10561 | G56: G. SELVARANI | H56: LPD10561 | G. SELVARANI
A57: WS57 | C57: OP-0057 | D57: Edge Inking | E57: OP-0057 | Edge Inking | F57: LPD09683 | G57: GIRIJA | H57: LPD09683 | GIRIJA
A58: WS58 | C58: OP-0058 | D58: Primer 1 | E58: OP-0058 | Primer 1 | F58: LPD07628 | G58: GNANAMMAL | H58: LPD07628 | GNANAMMAL
A59: WS59 | C59: OP-0059 | D59: Primer 2 | E59: OP-0059 | Primer 2 | F59: LPD10209 | G59: HAJEERA | H59: LPD10209 | HAJEERA
A60: WS60 | C60: OP-0060 | D60: Primer 3 | E60: OP-0060 | Primer 3 | F60: LPDS95749 | G60: HAJIMA MABOOB BASHA | H60: LPDS95749 | HAJIMA MABOOB BASHA
A61: WS61 | C61: OP-0061 | D61: Buffing | E61: OP-0061 | Buffing | F61: LPD12148 | G61: HASANUR JAMAN MOLLA | H61: LPD12148 | HASANUR JAMAN MOLLA
A62: WS62 | C62: OP-0062 | D62: Recutting facing Leather (1:5) | E62: OP-0062 | Recutting facing Leather (1:5) | F62: LPD12233 | G62: I RESHMA | H62: LPD12233 | I RESHMA
... A100: WS100 | C100: OP-0100 | D100: Pasting over shell | E100: OP-0100 | Pasting over shell | F100: LPD09670 | G100: M. SIDDIQUA | H100: LPD09670 | M. SIDDIQUA
C101: OP-0101 | D101: Attaching Right Gusset 2-Side With shell | E101: OP-0101 | Attaching Right Gusset 2-Side With shell | F101: LPD09393 | G101: M. USHA RANI | H101: LPD09393 | M. USHA RANI
C102: OP-0102 | D102: Pasting on zipper collar support kimlon bit & zip collar back | E102: OP-0102 | Pasting on zipper collar support kimlon bit & zip collar back | F102: LPD11279 | G102: M. ZEHRA | H102: LPD11279 | M. ZEHRA
C103: OP-0103 | D103: Attaching zipper collar support kimlon bit over zip collar back | E103: OP-0103 | Attaching zipper collar support kimlon bit over zip collar back | F103: LPD12248 | G103: MAFIJUL MOLLA | H103: LPD12248 | MAFIJUL MOLLA
C104: OP-0104 | D104: Pasting on kimlon (2nos) | E104: OP-0104 | Pasting on kimlon (2nos) | F104: LPD11204 | G104: MAHALAKSHMI | H104: LPD11204 | MAHALAKSHMI
C105: OP-0105 | D105: Pasting over Cc pkt lining | E105: OP-0105 | Pasting over Cc pkt lining | F105: LPD12247 | G105: MARUF HOSSAIN PIYADA | H105: LPD12247 | MARUF HOSSAIN PIYADA
C106: OP-0106 | D106: Attaching kimlon over cc pkt lining | E106: OP-0106 | Attaching kimlon over cc pkt lining | F106: LPD11314 | G106: MD ILYAS | H106: LPD11314 | MD ILYAS
C107: OP-0107 | D107: Pasting over Cc pkt | E107: OP-0107 | Pasting over Cc pkt | F107: LPD12221 | G107: MD YAMIN ALI MOLLA | H107: LPD12221 | MD YAMIN ALI MOLLA
C108: OP-0108 | D108: Pasting over Center stay | E108: OP-0108 | Pasting over Center stay | F108: LPD11278 | G108: MD. INTAKHAB | H108: LPD11278 | MD. INTAKHAB
C109: OP-0109 | D109: Attaching center stay over cc pkt | E109: OP-0109 | Attaching center stay over cc pkt | F109: LPD11618 | G109: MD. NASIM | H109: LPD11618 | MD. NASIM
C110: OP-0110 | D110: Pasting over window pkt | E110: OP-0110 | Pasting over window pkt | F110: LPD10281 | G110: MD. SHAMIM AHAMAD | H110: LPD10281 | MD. SHAMIM AHAMAD
C111: OP-0111 | D111: Attaching center stay over window pkt | E111: OP-0111 | Attaching center stay over window pkt | F111: LPD11532 | G111: MD. TANVEER | H111: LPD11532 | MD. TANVEER
C112: OP-0112 | D112: Pasting over shell | E112: OP-0112 | Pasting over shell | F112: LPD12238 | G112: MEENA S | H112: LPD12238 | MEENA S
... C211: OP_071 | D211: Quality Analysys | E211: OP_071 | Quality Analysys | F211: LPD08891 | G211: UMA MAHESWARI | H211: LPD08891 | UMA MAHESWARI
F212: LPD11454 | G212: USHA | H212: LPD11454 | USHA
...
