Workbook

Sheet Line Plan
A1: LINE PLAN UPLOAD
A3: LINE CODE | C3: Production line code. Auto-created if not in system.
A4: HALL NAME | C4: Hall/area name (used as line name if auto-creating the line).
A5: DATE | C5: Work date — YYYY-MM-DD format.
A6: PRODUCT CODE | B6: 35F2GTVF6V | C6: Style/product code. Auto-created if new.
A7: PRODUCT NAME | B7: BILLFOLD WALLET | C7: Full product name.
A8: BUYER NAME | C8: Buyer / brand name. Optional.
A9: PLAN MONTH | C9: Plan month (e.g. 2026-04). Optional.
A10: TARGET UNITS | C10: Daily target for this line. Required.
A11: CO PRODUCT CODE | C11: Optional — changeover product code.
A12: CO TARGET | C12: Optional — changeover target units.
A13: LINE LEADER | C13: Line leader name.
A14: WORKING TIME (s) | B14: 28800 | C14: Total working seconds per shift (9h). Used for Takt Time = Working Time ÷ Target.
A16: GROUP | B16: OSM ☑ | C16: WORKSTATION ▼ | D16: OP CODE (auto) | E16: SELECT OPERATION ▼ | F16: PROCESS TIME (s) | G16: CYCLE TIME (s) | H16: TAKT TIME (s) | I16: WORKLOAD | J16: SAH | K16: EMP CODE (auto) | L16: SELECT EMPLOYEE ▼
D17: ==IF(E17="","",IF(ISNUMBER(FIND("|",E17)),TRIM(LEFT(E17,FIND("|",E17)-1)),IF(ISNUMBER(MATCH(E17,Config!$C$1:$C$311,0)),E17,IFERROR(INDEX(Config!$C$1:$C$311,MATCH(E17,Config!$D$1:$D$311,0)),"")))) -> OP-0152 | E17: Pasting over First Patti & Kimlon | F17: 32 | G17: ==IF(C17="","",SUMIF($C$17:$C$502,C17,$F$17:$F$502)) | H17: ==IFERROR($B$14/$B$10,"") | I17: ==IFERROR(G17/H17,"") | J17: ==IF(F17="","",F17/3600) | K17: ==IF(L17="","",IF(ISNUMBER(FIND("|",L17)),TRIM(LEFT(L17,FIND("|",L17)-1)),IF(ISNUMBER(MATCH(L17,Config!$F$1:$F$853,0)),L17,IFERROR(INDEX(Config!$F$1:$F$853,MATCH(L17,Config!$G$1:$G$853,0)),""))))
D18: ==IF(E18="","",IF(ISNUMBER(FIND("|",E18)),TRIM(LEFT(E18,FIND("|",E18)-1)),IF(ISNUMBER(MATCH(E18,Config!$C$1:$C$311,0)),E18,IFERROR(INDEX(Config!$C$1:$C$311,MATCH(E18,Config!$D$1:$D$311,0)),"")))) -> OP-0153 | E18: Attaching Kimlon over First Patti Lining | F18: 16 | G18: ==IF(C18="","",SUMIF($C$17:$C$502,C18,$F$17:$F$502)) | H18: ==IFERROR($B$14/$B$10,"") | I18: ==IFERROR(G18/H18,"") | J18: ==IF(F18="","",F18/3600) | K18: ==IF(L18="","",IF(ISNUMBER(FIND("|",L18)),TRIM(LEFT(L18,FIND("|",L18)-1)),IF(ISNUMBER(MATCH(L18,Config!$F$1:$F$853,0)),L18,IFERROR(INDEX(Config!$F$1:$F$853,MATCH(L18,Config!$G$1:$G$853,0)),"")))) | L18: ==IFERROR(INDEX($L$17:L17,MATCH(C18,$C$17:C17,0)),"")
D19: ==IF(E19="","",IF(ISNUMBER(FIND("|",E19)),TRIM(LEFT(E19,FIND("|",E19)-1)),IF(ISNUMBER(MATCH(E19,Config!$C$1:$C$311,0)),E19,IFERROR(INDEX(Config!$C$1:$C$311,MATCH(E19,Config!$D$1:$D$311,0)),"")))) -> OP-0154 | E19: Stitching First Patti with Lining on Bottom Side (1-No) | F19: 14 | G19: ==IF(C19="","",SUMIF($C$17:$C$502,C19,$F$17:$F$502)) | H19: ==IFERROR($B$14/$B$10,"") | I19: ==IFERROR(G19/H19,"") | J19: ==IF(F19="","",F19/3600) | K19: ==IF(L19="","",IF(ISNUMBER(FIND("|",L19)),TRIM(LEFT(L19,FIND("|",L19)-1)),IF(ISNUMBER(MATCH(L19,Config!$F$1:$F$853,0)),L19,IFERROR(INDEX(Config!$F$1:$F$853,MATCH(L19,Config!$G$1:$G$853,0)),"")))) | L19: ==IFERROR(INDEX($L$17:L18,MATCH(C19,$C$17:C18,0)),"")
D20: ==IF(E20="","",IF(ISNUMBER(FIND("|",E20)),TRIM(LEFT(E20,FIND("|",E20)-1)),IF(ISNUMBER(MATCH(E20,Config!$C$1:$C$311,0)),E20,IFERROR(INDEX(Config!$C$1:$C$311,MATCH(E20,Config!$D$1:$D$311,0)),"")))) -> OP-0155 | E20: Stitching Step Patti with Lining on Bottom Side (6-Nos) | F20: 35 | G20: ==IF(C20="","",SUMIF($C$17:$C$502,C20,$F$17:$F$502)) | H20: ==IFERROR($B$14/$B$10,"") | I20: ==IFERROR(G20/H20,"") | J20: ==IF(F20="","",F20/3600) | K20: ==IF(L20="","",IF(ISNUMBER(FIND("|",L20)),TRIM(LEFT(L20,FIND("|",L20)-1)),IF(ISNUMBER(MATCH(L20,Config!$F$1:$F$853,0)),L20,IFERROR(INDEX(Config!$F$1:$F$853,MATCH(L20,Config!$G$1:$G$853,0)),"")))) | L20: ==IFERROR(INDEX($L$17:L19,MATCH(C20,$C$17:C19,0)),"")
D21: ==IF(E21="","",IF(ISNUMBER(FIND("|",E21)),TRIM(LEFT(E21,FIND("|",E21)-1)),IF(ISNUMBER(MATCH(E21,Config!$C$1:$C$311,0)),E21,IFERROR(INDEX(Config!$C$1:$C$311,MATCH(E21,Config!$D$1:$D$311,0)),"")))) -> OP-0156 | E21: Stitching Step Patti with Lining on Top Side (6-Nos) | F21: 35 | G21: ==IF(C21="","",SUMIF($C$17:$C$502,C21,$F$17:$F$502)) | H21: ==IFERROR($B$14/$B$10,"") | I21: ==IFERROR(G21/H21,"") | J21: ==IF(F21="","",F21/3600) | K21: ==IF(L21="","",IF(ISNUMBER(FIND("|",L21)),TRIM(LEFT(L21,FIND("|",L21)-1)),IF(ISNUMBER(MATCH(L21,Config!$F$1:$F$853,0)),L21,IFERROR(INDEX(Config!$F$1:$F$853,MATCH(L21,Config!$G$1:$G$853,0)),"")))) | L21: ==IFERROR(INDEX($L$17:L20,MATCH(C21,$C$17:C20,0)),"")
D22: ==IF(E22="","",IF(ISNUMBER(FIND("|",E22)),TRIM(LEFT(E22,FIND("|",E22)-1)),IF(ISNUMBER(MATCH(E22,Config!$C$1:$C$311,0)),E22,IFERROR(INDEX(Config!$C$1:$C$311,MATCH(E22,Config!$D$1:$D$311,0)),"")))) -> OP-0157 | E22: Stitching Last Patti with Lining on Bottom Side (1-No) | F22: 7 | G22: ==IF(C22="","",SUMIF($C$17:$C$502,C22,$F$17:$F$502)) | H22: ==IFERROR($B$14/$B$10,"") | I22: ==IFERROR(G22/H22,"") | J22: ==IF(F22="","",F22/3600) | K22: ==IF(L22="","",IF(ISNUMBER(FIND("|",L22)),TRIM(LEFT(L22,FIND("|",L22)-1)),IF(ISNUMBER(MATCH(L22,Config!$F$1:$F$853,0)),L22,IFERROR(INDEX(Config!$F$1:$F$853,MATCH(L22,Config!$G$1:$G$853,0)),"")))) | L22: ==IFERROR(INDEX($L$17:L21,MATCH(C22,$C$17:C21,0)),"")
D23: ==IF(E23="","",IF(ISNUMBER(FIND("|",E23)),TRIM(LEFT(E23,FIND("|",E23)-1)),IF(ISNUMBER(MATCH(E23,Config!$C$1:$C$311,0)),E23,IFERROR(INDEX(Config!$C$1:$C$311,MATCH(E23,Config!$D$1:$D$311,0)),"")))) -> OP-0158 | E23: Stitching Last Patti with Lining on Top Side (1-No) | F23: 7 | G23: ==IF(C23="","",SUMIF($C$17:$C$502,C23,$F$17:$F$502)) | H23: ==IFERROR($B$14/$B$10,"") | I23: ==IFERROR(G23/H23,"") | J23: ==IF(F23="","",F23/3600) | K23: ==IF(L23="","",IF(ISNUMBER(FIND("|",L23)),TRIM(LEFT(L23,FIND("|",L23)-1)),IF(ISNUMBER(MATCH(L23,Config!$F$1:$F$853,0)),L23,IFERROR(INDEX(Config!$F$1:$F$853,MATCH(L23,Config!$G$1:$G$853,0)),"")))) | L23: ==IFERROR(INDEX($L$17:L22,MATCH(C23,$C$17:C22,0)),"")
D24: ==IF(E24="","",IF(ISNUMBER(FIND("|",E24)),TRIM(LEFT(E24,FIND("|",E24)-1)),IF(ISNUMBER(MATCH(E24,Config!$C$1:$C$311,0)),E24,IFERROR(INDEX(Config!$C$1:$C$311,MATCH(E24,Config!$D$1:$D$311,0)),"")))) -> OP-0159 | E24: Stitching Window on Top Side & Cutting (1-No) | F24: 8 | G24: ==IF(C24="","",SUMIF($C$17:$C$502,C24,$F$17:$F$502)) | H24: ==IFERROR($B$14/$B$10,"") | I24: ==IFERROR(G24/H24,"") | J24: ==IF(F24="","",F24/3600) | K24: ==IF(L24="","",IF(ISNUMBER(FIND("|",L24)),TRIM(LEFT(L24,FIND("|",L24)-1)),IF(ISNUMBER(MATCH(L24,Config!$F$1:$F$853,0)),L24,IFERROR(INDEX(Config!$F$1:$F$853,MATCH(L24,Config!$G$1:$G$853,0)),"")))) | L24: ==IFERROR(INDEX($L$17:L23,MATCH(C24,$C$17:C23,0)),"")
D25: ==IF(E25="","",IF(ISNUMBER(FIND("|",E25)),TRIM(LEFT(E25,FIND("|",E25)-1)),IF(ISNUMBER(MATCH(E25,Config!$C$1:$C$311,0)),E25,IFERROR(INDEX(Config!$C$1:$C$311,MATCH(E25,Config!$D$1:$D$311,0)),"")))) -> OP-0160 | E25: Pasting over Top Patti & Step Patti (4-Nos) | F25: 20 | G25: ==IF(C25="","",SUMIF($C$17:$C$502,C25,$F$17:$F$502)) | H25: ==IFERROR($B$14/$B$10,"") | I25: ==IFERROR(G25/H25,"") | J25: ==IF(F25="","",F25/3600) | K25: ==IF(L25="","",IF(ISNUMBER(FIND("|",L25)),TRIM(LEFT(L25,FIND("|",L25)-1)),IF(ISNUMBER(MATCH(L25,Config!$F$1:$F$853,0)),L25,IFERROR(INDEX(Config!$F$1:$F$853,MATCH(L25,Config!$G$1:$G$853,0)),"")))) | L25: ==IFERROR(INDEX($L$17:L24,MATCH(C25,$C$17:C24,0)),"")
D26: ==IF(E26="","",IF(ISNUMBER(FIND("|",E26)),TRIM(LEFT(E26,FIND("|",E26)-1)),IF(ISNUMBER(MATCH(E26,Config!$C$1:$C$311,0)),E26,IFERROR(INDEX(Config!$C$1:$C$311,MATCH(E26,Config!$D$1:$D$311,0)),"")))) -> OP-0161 | E26: Attaching Step Patti over First Patti | F26: 24 | G26: ==IF(C26="","",SUMIF($C$17:$C$502,C26,$F$17:$F$502)) | H26: ==IFERROR($B$14/$B$10,"") | I26: ==IFERROR(G26/H26,"") | J26: ==IF(F26="","",F26/3600) | K26: ==IF(L26="","",IF(ISNUMBER(FIND("|",L26)),TRIM(LEFT(L26,FIND("|",L26)-1)),IF(ISNUMBER(MATCH(L26,Config!$F$1:$F$853,0)),L26,IFERROR(INDEX(Config!$F$1:$F$853,MATCH(L26,Config!$G$1:$G$853,0)),"")))) | L26: ==IFERROR(INDEX($L$17:L25,MATCH(C26,$C$17:C25,0)),"")
D27: ==IF(E27="","",IF(ISNUMBER(FIND("|",E27)),TRIM(LEFT(E27,FIND("|",E27)-1)),IF(ISNUMBER(MATCH(E27,Config!$C$1:$C$311,0)),E27,IFERROR(INDEX(Config!$C$1:$C$311,MATCH(E27,Config!$D$1:$D$311,0)),"")))) -> OP-0162 | E27: Stitching Step Patti with First Patti in AMS (Card Showing 2-Nos) | F27: 13 | G27: ==IF(C27="","",SUMIF($C$17:$C$502,C27,$F$17:$F$502)) | H27: ==IFERROR($B$14/$B$10,"") | I27: ==IFERROR(G27/H27,"") | J27: ==IF(F27="","",F27/3600) | K27: ==IF(L27="","",IF(ISNUMBER(FIND("|",L27)),TRIM(LEFT(L27,FIND("|",L27)-1)),IF(ISNUMBER(MATCH(L27,Config!$F$1:$F$853,0)),L27,IFERROR(INDEX(Config!$F$1:$F$853,MATCH(L27,Config!$G$1:$G$853,0)),"")))) | L27: ==IFERROR(INDEX($L$17:L26,MATCH(C27,$C$17:C26,0)),"")
D28: ==IF(E28="","",IF(ISNUMBER(FIND("|",E28)),TRIM(LEFT(E28,FIND("|",E28)-1)),IF(ISNUMBER(MATCH(E28,Config!$C$1:$C$311,0)),E28,IFERROR(INDEX(Config!$C$1:$C$311,MATCH(E28,Config!$D$1:$D$311,0)),"")))) -> OP-0163 | E28: Stitching Step Patti with First Patti in AMS (Card Showing 3-Nos) | F28: 19.5 | G28: ==IF(C28="","",SUMIF($C$17:$C$502,C28,$F$17:$F$502)) | H28: ==IFERROR($B$14/$B$10,"") | I28: ==IFERROR(G28/H28,"") | J28: ==IF(F28="","",F28/3600) | K28: ==IF(L28="","",IF(ISNUMBER(FIND("|",L28)),TRIM(LEFT(L28,FIND("|",L28)-1)),IF(ISNUMBER(MATCH(L28,Config!$F$1:$F$853,0)),L28,IFERROR(INDEX(Config!$F$1:$F$853,MATCH(L28,Config!$G$1:$G$853,0)),"")))) | L28: ==IFERROR(INDEX($L$17:L27,MATCH(C28,$C$17:C27,0)),"")
D29: ==IF(E29="","",IF(ISNUMBER(FIND("|",E29)),TRIM(LEFT(E29,FIND("|",E29)-1)),IF(ISNUMBER(MATCH(E29,Config!$C$1:$C$311,0)),E29,IFERROR(INDEX(Config!$C$1:$C$311,MATCH(E29,Config!$D$1:$D$311,0)),"")))) -> OP-0164 | E29: Stitching Stamp with Lining on Top Side & Cutting in AMS (1-No) | F29: 8 | G29: ==IF(C29="","",SUMIF($C$17:$C$502,C29,$F$17:$F$502)) | H29: ==IFERROR($B$14/$B$10,"") | I29: ==IFERROR(G29/H29,"") | J29: ==IF(F29="","",F29/3600) | K29: ==IF(L29="","",IF(ISNUMBER(FIND("|",L29)),TRIM(LEFT(L29,FIND("|",L29)-1)),IF(ISNUMBER(MATCH(L29,Config!$F$1:$F$853,0)),L29,IFERROR(INDEX(Config!$F$1:$F$853,MATCH(L29,Config!$G$1:$G$853,0)),"")))) | L29: ==IFERROR(INDEX($L$17:L28,MATCH(C29,$C$17:C28,0)),"")
... D208: ==IF(E208="","",IF(ISNUMBER(FIND("|",E208)),TRIM(LEFT(E208,FIND("|",E208)-1)),IF(ISNUMBER(MATCH(E208,Config!$C$1:$C$311,0)),E208,IFERROR(INDEX(Config!$C$1:$C$311,MATCH(E208,Config!$D$1:$D$311,0)),"")))) -> OP-0323 | E208: Final Shapping of Md Bifld Zip CN Wallet | F208: 28 | G208: ==IF(C208="","",SUMIF($C$17:$C$502,C208,$F$17:$F$502)) | H208: ==IFERROR($B$14/$B$10,"") | I208: ==IFERROR(G208/H208,"") | J208: ==IF(F208="","",F208/3600) | K208: ==IF(L208="","",IF(ISNUMBER(FIND("|",L208)),TRIM(LEFT(L208,FIND("|",L208)-1)),IF(ISNUMBER(MATCH(L208,Config!$F$1:$F$853,0)),L208,IFERROR(INDEX(Config!$F$1:$F$853,MATCH(L208,Config!$G$1:$G$853,0)),"")))) | L208: ==IFERROR(INDEX($L$17:L207,MATCH(C208,$C$17:C207,0)),"")
D209: ==IF(E209="","",IF(ISNUMBER(FIND("|",E209)),TRIM(LEFT(E209,FIND("|",E209)-1)),IF(ISNUMBER(MATCH(E209,Config!$C$1:$C$311,0)),E209,IFERROR(INDEX(Config!$C$1:$C$311,MATCH(E209,Config!$D$1:$D$311,0)),"")))) | G209: ==IF(C209="","",SUMIF($C$17:$C$502,C209,$F$17:$F$502)) | H209: ==IFERROR($B$14/$B$10,"") | I209: ==IFERROR(G209/H209,"") | J209: ==IF(F209="","",F209/3600) | K209: ==IF(L209="","",IF(ISNUMBER(FIND("|",L209)),TRIM(LEFT(L209,FIND("|",L209)-1)),IF(ISNUMBER(MATCH(L209,Config!$F$1:$F$853,0)),L209,IFERROR(INDEX(Config!$F$1:$F$853,MATCH(L209,Config!$G$1:$G$853,0)),"")))) | L209: ==IFERROR(INDEX($L$17:L208,MATCH(C209,$C$17:C208,0)),"")
D210: ==IF(E210="","",IF(ISNUMBER(FIND("|",E210)),TRIM(LEFT(E210,FIND("|",E210)-1)),IF(ISNUMBER(MATCH(E210,Config!$C$1:$C$311,0)),E210,IFERROR(INDEX(Config!$C$1:$C$311,MATCH(E210,Config!$D$1:$D$311,0)),"")))) | G210: ==IF(C210="","",SUMIF($C$17:$C$502,C210,$F$17:$F$502)) | H210: ==IFERROR($B$14/$B$10,"") | I210: ==IFERROR(G210/H210,"") | J210: ==IF(F210="","",F210/3600) | K210: ==IF(L210="","",IF(ISNUMBER(FIND("|",L210)),TRIM(LEFT(L210,FIND("|",L210)-1)),IF(ISNUMBER(MATCH(L210,Config!$F$1:$F$853,0)),L210,IFERROR(INDEX(Config!$F$1:$F$853,MATCH(L210,Config!$G$1:$G$853,0)),"")))) | L210: ==IFERROR(INDEX($L$17:L209,MATCH(C210,$C$17:C209,0)),"")
D211: ==IF(E211="","",IF(ISNUMBER(FIND("|",E211)),TRIM(LEFT(E211,FIND("|",E211)-1)),IF(ISNUMBER(MATCH(E211,Config!$C$1:$C$311,0)),E211,IFERROR(INDEX(Config!$C$1:$C$311,MATCH(E211,Config!$D$1:$D$311,0)),"")))) | G211: ==IF(C211="","",SUMIF($C$17:$C$502,C211,$F$17:$F$502)) | H211: ==IFERROR($B$14/$B$10,"") | I211: ==IFERROR(G211/H211,"") | J211: ==IF(F211="","",F211/3600) | K211: ==IF(L211="","",IF(ISNUMBER(FIND("|",L211)),TRIM(LEFT(L211,FIND("|",L211)-1)),IF(ISNUMBER(MATCH(L211,Config!$F$1:$F$853,0)),L211,IFERROR(INDEX(Config!$F$1:$F$853,MATCH(L211,Config!$G$1:$G$853,0)),"")))) | L211: ==IFERROR(INDEX($L$17:L210,MATCH(C211,$C$17:C210,0)),"")
D212: ==IF(E212="","",IF(ISNUMBER(FIND("|",E212)),TRIM(LEFT(E212,FIND("|",E212)-1)),IF(ISNUMBER(MATCH(E212,Config!$C$1:$C$311,0)),E212,IFERROR(INDEX(Config!$C$1:$C$311,MATCH(E212,Config!$D$1:$D$311,0)),"")))) | G212: ==IF(C212="","",SUMIF($C$17:$C$502,C212,$F$17:$F$502)) | H212: ==IFERROR($B$14/$B$10,"") | I212: ==IFERROR(G212/H212,"") | J212: ==IF(F212="","",F212/3600) | K212: ==IF(L212="","",IF(ISNUMBER(FIND("|",L212)),TRIM(LEFT(L212,FIND("|",L212)-1)),IF(ISNUMBER(MATCH(L212,Config!$F$1:$F$853,0)),L212,IFERROR(INDEX(Config!$F$1:$F$853,MATCH(L212,Config!$G$1:$G$853,0)),"")))) | L212: ==IFERROR(INDEX($L$17:L211,MATCH(C212,$C$17:C211,0)),"")
D213: ==IF(E213="","",IF(ISNUMBER(FIND("|",E213)),TRIM(LEFT(E213,FIND("|",E213)-1)),IF(ISNUMBER(MATCH(E213,Config!$C$1:$C$311,0)),E213,IFERROR(INDEX(Config!$C$1:$C$311,MATCH(E213,Config!$D$1:$D$311,0)),"")))) | G213: ==IF(C213="","",SUMIF($C$17:$C$502,C213,$F$17:$F$502)) | H213: ==IFERROR($B$14/$B$10,"") | I213: ==IFERROR(G213/H213,"") | J213: ==IF(F213="","",F213/3600) | K213: ==IF(L213="","",IF(ISNUMBER(FIND("|",L213)),TRIM(LEFT(L213,FIND("|",L213)-1)),IF(ISNUMBER(MATCH(L213,Config!$F$1:$F$853,0)),L213,IFERROR(INDEX(Config!$F$1:$F$853,MATCH(L213,Config!$G$1:$G$853,0)),"")))) | L213: ==IFERROR(INDEX($L$17:L212,MATCH(C213,$C$17:C212,0)),"")
D214: ==IF(E214="","",IF(ISNUMBER(FIND("|",E214)),TRIM(LEFT(E214,FIND("|",E214)-1)),IF(ISNUMBER(MATCH(E214,Config!$C$1:$C$311,0)),E214,IFERROR(INDEX(Config!$C$1:$C$311,MATCH(E214,Config!$D$1:$D$311,0)),"")))) | G214: ==IF(C214="","",SUMIF($C$17:$C$502,C214,$F$17:$F$502)) | H214: ==IFERROR($B$14/$B$10,"") | I214: ==IFERROR(G214/H214,"") | J214: ==IF(F214="","",F214/3600) | K214: ==IF(L214="","",IF(ISNUMBER(FIND("|",L214)),TRIM(LEFT(L214,FIND("|",L214)-1)),IF(ISNUMBER(MATCH(L214,Config!$F$1:$F$853,0)),L214,IFERROR(INDEX(Config!$F$1:$F$853,MATCH(L214,Config!$G$1:$G$853,0)),"")))) | L214: ==IFERROR(INDEX($L$17:L213,MATCH(C214,$C$17:C213,0)),"")
D215: ==IF(E215="","",IF(ISNUMBER(FIND("|",E215)),TRIM(LEFT(E215,FIND("|",E215)-1)),IF(ISNUMBER(MATCH(E215,Config!$C$1:$C$311,0)),E215,IFERROR(INDEX(Config!$C$1:$C$311,MATCH(E215,Config!$D$1:$D$311,0)),"")))) | G215: ==IF(C215="","",SUMIF($C$17:$C$502,C215,$F$17:$F$502)) | H215: ==IFERROR($B$14/$B$10,"") | I215: ==IFERROR(G215/H215,"") | J215: ==IF(F215="","",F215/3600) | K215: ==IF(L215="","",IF(ISNUMBER(FIND("|",L215)),TRIM(LEFT(L215,FIND("|",L215)-1)),IF(ISNUMBER(MATCH(L215,Config!$F$1:$F$853,0)),L215,IFERROR(INDEX(Config!$F$1:$F$853,MATCH(L215,Config!$G$1:$G$853,0)),"")))) | L215: ==IFERROR(INDEX($L$17:L214,MATCH(C215,$C$17:C214,0)),"")
D216: ==IF(E216="","",IF(ISNUMBER(FIND("|",E216)),TRIM(LEFT(E216,FIND("|",E216)-1)),IF(ISNUMBER(MATCH(E216,Config!$C$1:$C$311,0)),E216,IFERROR(INDEX(Config!$C$1:$C$311,MATCH(E216,Config!$D$1:$D$311,0)),"")))) | G216: ==IF(C216="","",SUMIF($C$17:$C$502,C216,$F$17:$F$502)) | H216: ==IFERROR($B$14/$B$10,"") | I216: ==IFERROR(G216/H216,"") | J216: ==IF(F216="","",F216/3600) | K216: ==IF(L216="","",IF(ISNUMBER(FIND("|",L216)),TRIM(LEFT(L216,FIND("|",L216)-1)),IF(ISNUMBER(MATCH(L216,Config!$F$1:$F$853,0)),L216,IFERROR(INDEX(Config!$F$1:$F$853,MATCH(L216,Config!$G$1:$G$853,0)),"")))) | L216: ==IFERROR(INDEX($L$17:L215,MATCH(C216,$C$17:C215,0)),"")
D217: ==IF(E217="","",IF(ISNUMBER(FIND("|",E217)),TRIM(LEFT(E217,FIND("|",E217)-1)),IF(ISNUMBER(MATCH(E217,Config!$C$1:$C$311,0)),E217,IFERROR(INDEX(Config!$C$1:$C$311,MATCH(E217,Config!$D$1:$D$311,0)),"")))) | G217: ==IF(C217="","",SUMIF($C$17:$C$502,C217,$F$17:$F$502)) | H217: ==IFERROR($B$14/$B$10,"") | I217: ==IFERROR(G217/H217,"") | J217: ==IF(F217="","",F217/3600) | K217: ==IF(L217="","",IF(ISNUMBER(FIND("|",L217)),TRIM(LEFT(L217,FIND("|",L217)-1)),IF(ISNUMBER(MATCH(L217,Config!$F$1:$F$853,0)),L217,IFERROR(INDEX(Config!$F$1:$F$853,MATCH(L217,Config!$G$1:$G$853,0)),"")))) | L217: ==IFERROR(INDEX($L$17:L216,MATCH(C217,$C$17:C216,0)),"")
D218: ==IF(E218="","",IF(ISNUMBER(FIND("|",E218)),TRIM(LEFT(E218,FIND("|",E218)-1)),IF(ISNUMBER(MATCH(E218,Config!$C$1:$C$311,0)),E218,IFERROR(INDEX(Config!$C$1:$C$311,MATCH(E218,Config!$D$1:$D$311,0)),"")))) | G218: ==IF(C218="","",SUMIF($C$17:$C$502,C218,$F$17:$F$502)) | H218: ==IFERROR($B$14/$B$10,"") | I218: ==IFERROR(G218/H218,"") | J218: ==IF(F218="","",F218/3600) | K218: ==IF(L218="","",IF(ISNUMBER(FIND("|",L218)),TRIM(LEFT(L218,FIND("|",L218)-1)),IF(ISNUMBER(MATCH(L218,Config!$F$1:$F$853,0)),L218,IFERROR(INDEX(Config!$F$1:$F$853,MATCH(L218,Config!$G$1:$G$853,0)),"")))) | L218: ==IFERROR(INDEX($L$17:L217,MATCH(C218,$C$17:C217,0)),"")
D219: ==IF(E219="","",IF(ISNUMBER(FIND("|",E219)),TRIM(LEFT(E219,FIND("|",E219)-1)),IF(ISNUMBER(MATCH(E219,Config!$C$1:$C$311,0)),E219,IFERROR(INDEX(Config!$C$1:$C$311,MATCH(E219,Config!$D$1:$D$311,0)),"")))) | G219: ==IF(C219="","",SUMIF($C$17:$C$502,C219,$F$17:$F$502)) | H219: ==IFERROR($B$14/$B$10,"") | I219: ==IFERROR(G219/H219,"") | J219: ==IF(F219="","",F219/3600) | K219: ==IF(L219="","",IF(ISNUMBER(FIND("|",L219)),TRIM(LEFT(L219,FIND("|",L219)-1)),IF(ISNUMBER(MATCH(L219,Config!$F$1:$F$853,0)),L219,IFERROR(INDEX(Config!$F$1:$F$853,MATCH(L219,Config!$G$1:$G$853,0)),"")))) | L219: ==IFERROR(INDEX($L$17:L218,MATCH(C219,$C$17:C218,0)),"")
D220: ==IF(E220="","",IF(ISNUMBER(FIND("|",E220)),TRIM(LEFT(E220,FIND("|",E220)-1)),IF(ISNUMBER(MATCH(E220,Config!$C$1:$C$311,0)),E220,IFERROR(INDEX(Config!$C$1:$C$311,MATCH(E220,Config!$D$1:$D$311,0)),"")))) | G220: ==IF(C220="","",SUMIF($C$17:$C$502,C220,$F$17:$F$502)) | H220: ==IFERROR($B$14/$B$10,"") | I220: ==IFERROR(G220/H220,"") | J220: ==IF(F220="","",F220/3600) | K220: ==IF(L220="","",IF(ISNUMBER(FIND("|",L220)),TRIM(LEFT(L220,FIND("|",L220)-1)),IF(ISNUMBER(MATCH(L220,Config!$F$1:$F$853,0)),L220,IFERROR(INDEX(Config!$F$1:$F$853,MATCH(L220,Config!$G$1:$G$853,0)),"")))) | L220: ==IFERROR(INDEX($L$17:L219,MATCH(C220,$C$17:C219,0)),"")
...

Sheet Config
A1: WS01 | B1: G1 | C1: OP-0011 | D1: Cleaning | E1: OP-0011 | Cleaning | F1: LPDS95715 | G1: A ANWAR BASHA | H1: LPDS95715 | A ANWAR BASHA | I1: ☐
A2: WS02 | B2: G2 | C2: OP-0014 | D2: Heating | E2: OP-0014 | Heating | F2: LPDS95761 | G2: A FATHIMA | H2: LPDS95761 | A FATHIMA | I2: ☑
A3: WS03 | B3: G3 | C3: OP-0015 | D3: board with lining attatching & 1st primer | E3: OP-0015 | board with lining attatching & 1st primer | F3: LPDS95657 | G3: A JOTHI | H3: LPDS95657 | A JOTHI
A4: WS04 | B4: G4 | C4: OP-0016 | D4: die process | E4: OP-0016 | die process | F4: LPD11959 | G4: A MEENAKSHI | H4: LPD11959 | A MEENAKSHI
A5: WS05 | B5: G5 | C5: OP-0017 | D5: Pasting on patti (5*1 Nos) | E5: OP-0017 | Pasting on patti (5*1 Nos) | F5: LPD12059 | G5: A MUBARAK BASHA | H5: LPD12059 | A MUBARAK BASHA
A6: WS06 | B6: G6 | C6: OP-0018 | D6: Attaching step patti (4*1 Nos) | E6: OP-0018 | Attaching step patti (4*1 Nos) | F6: LPDS95642 | G6: A MUNNI | H6: LPDS95642 | A MUNNI
A7: WS07 | B7: G7 | C7: OP-0019 | D7: Pasting on stamp & pkt (1-Nos) | E7: OP-0019 | Pasting on stamp & pkt (1-Nos) | F7: LPD12207 | G7: A P MD ASIF | H7: LPD12207 | A P MD ASIF
A8: WS08 | B8: G8 | C8: OP-0020 | D8: Attaching stamp with cc pkt | E8: OP-0020 | Attaching stamp with cc pkt | F8: LPDS95379 | G8: A PARVEEN | H8: LPDS95379 | A PARVEEN
A9: WS09 | B9: G9 | C9: OP-0021 | D9: Pasting on patti (4*1 Nos) | E9: OP-0021 | Pasting on patti (4*1 Nos) | F9: LPDS95268 | G9: A RASHEEDA | H9: LPDS95268 | A RASHEEDA
A10: WS10 | B10: G10 | C10: OP-0022 | D10: Attaching step patti (3*1 Nos) | E10: OP-0022 | Attaching step patti (3*1 Nos) | F10: LPDS94966 | G10: A SHARMILA | H10: LPDS94966 | A SHARMILA
A11: WS11 | B11: G11 | C11: OP-0023 | D11: Stitching the lining (4*1 Nos) | E11: OP-0023 | Stitching the lining (4*1 Nos) | F11: LPDS95012 | G11: A SUMAIYA BANU | H11: LPDS95012 | A SUMAIYA BANU
A12: WS12 | B12: G12 | C12: OP-0024 | D12: Stitching closing lining (1*1 Nos) | E12: OP-0024 | Stitching closing lining (1*1 Nos) | F12: LPD09853 | G12: A. ABDUL SUBAN | H12: LPD09853 | A. ABDUL SUBAN
A13: WS13 | B13: G13 | C13: OP-0025 | D13: Stitching the lining (3*1 Nos) | E13: OP-0025 | Stitching the lining (3*1 Nos) | F13: LPD02946 | G13: A. ALEMELU | H13: LPD02946 | A. ALEMELU
A14: WS14 | B14: G14 | C14: OP-0026 | D14: Stitching the lining (1*1 Nos) | E14: OP-0026 | Stitching the lining (1*1 Nos) | F14: LPD10931 | G14: A. AMEEN BASHA | H14: LPD10931 | A. AMEEN BASHA
... A50: WS50 | B50: G50 | C50: OP-0062 | D50: Recutting facing Leather (1:5) | E50: OP-0062 | Recutting facing Leather (1:5) | F50: LPD07027 | G50: A. SAMIULLAH | H50: LPD07027 | A. SAMIULLAH
A51: WS51 | C51: OP-0063 | D51: Recutting Top Leather (1:5) | E51: OP-0063 | Recutting Top Leather (1:5) | F51: LPD07993 | G51: A. SHABEENA | H51: LPD07993 | A. SHABEENA
A52: WS52 | C52: OP-0064 | D52: Recutting Top | E52: OP-0064 | Recutting Top | F52: LPD09931 | G52: A. SHAHUL HAMEED | H52: LPD09931 | A. SHAHUL HAMEED
A53: WS53 | C53: OP-0065 | D53: Recutting zip collar PU | E53: OP-0065 | Recutting zip collar PU | F53: LPD07673 | G53: A. SHAKILA | H53: LPD07673 | A. SHAKILA
A54: WS54 | C54: OP-0066 | D54: Foil Embossing on cc pkt | E54: OP-0066 | Foil Embossing on cc pkt | F54: LPD09740 | G54: A. SHAMSHAD | H54: LPD09740 | A. SHAMSHAD
A55: WS55 | C55: OP-0067 | D55: inserting & Pressing snap male button (1-Nos) | E55: OP-0067 | inserting & Pressing snap male button (1-Nos) | F55: LPD10936 | G55: A. SHAMSHATH BI | H55: LPD10936 | A. SHAMSHATH BI
A56: WS56 | C56: OP-0068 | D56: Revitting Female button on Top | E56: OP-0068 | Revitting Female button on Top | F56: LPD11215 | G56: A. SHYAMALA | H56: LPD11215 | A. SHYAMALA
A57: WS57 | C57: OP-0069 | D57: Grinding Logo on Top | E57: OP-0069 | Grinding Logo on Top | F57: LPD05396 | G57: A. SIVA SAKTHI | H57: LPD05396 | A. SIVA SAKTHI
A58: WS58 | C58: OP-0070 | D58: Pressing logo on Top | E58: OP-0070 | Pressing logo on Top | F58: LPD10040 | G58: A. SUBEDHA | H58: LPD10040 | A. SUBEDHA
A59: WS59 | C59: OP-0071 | D59: Attaching Self adhesive logo cover kimlon | E59: OP-0071 | Attaching Self adhesive logo cover kimlon | F59: LPD11513 | G59: A. SUHAIL AHMED | H59: LPD11513 | A. SUHAIL AHMED
A60: WS60 | C60: OP-0072 | D60: Pasting on top | E60: OP-0072 | Pasting on top | F60: LPD07362 | G60: A. SUNDHARI | H60: LPD07362 | A. SUNDHARI
A61: WS61 | C61: OP-0073 | D61: Pasting on nonwoven(L/R) | E61: OP-0073 | Pasting on nonwoven(L/R) | F61: LPD05724 | G61: A. VIJAYALAKSHMI | H61: LPD05724 | A. VIJAYALAKSHMI
A62: WS62 | C62: OP-0074 | D62: Pasting & Attaching mica (2) over top | E62: OP-0074 | Pasting & Attaching mica (2) over top | F62: LPD07910 | G62: A. WAHIDA BANU | H62: LPD07910 | A. WAHIDA BANU
... A100: WS100 | C100: OP-0112 | D100: Pasting over shell | E100: OP-0112 | Pasting over shell | F100: LPD11755 | G100: ANGEL ROSELIN | H100: LPD11755 | ANGEL ROSELIN
C101: OP-0113 | D101: Pasting over Center stay pkt | E101: OP-0113 | Pasting over Center stay pkt | F101: LPD08664 | G101: ANITHA | H101: LPD08664 | ANITHA
C102: OP-0114 | D102: Attaching center pkt with shell | E102: OP-0114 | Attaching center pkt with shell | F102: LPDS95480 | G102: ANITHA SASIKUMAR | H102: LPDS95480 | ANITHA SASIKUMAR
C103: OP-0115 | D103: Pasting over Center stay lining | E103: OP-0115 | Pasting over Center stay lining | F103: LPD10617 | G103: ANJALI | H103: LPD10617 | ANJALI
C104: OP-0116 | D104: Attaching with closing center stay lining with shell closing | E104: OP-0116 | Attaching with closing center stay lining with shell closing | F104: LPDS94796 | G104: ANJUGAM S | H104: LPDS94796 | ANJUGAM S
C105: OP-0117 | D105: Stitching L&R Shell & zip collar | E105: OP-0117 | Stitching L&R Shell & zip collar | F105: LPD10566 | G105: ANOWAR HUSSIAN | H105: LPD10566 | ANOWAR HUSSIAN
C106: OP-0118 | D106: Stitching center stay over cc pkt | E106: OP-0118 | Stitching center stay over cc pkt | F106: LPD12199 | G106: ANUSUYA | H106: LPD12199 | ANUSUYA
C107: OP-0119 | D107: Pasting over backwall lining | E107: OP-0119 | Pasting over backwall lining | F107: LPD11479 | G107: ARAVALLI | H107: LPD11479 | ARAVALLI
C108: OP-0120 | D108: Attaching centerstay /window pkt over backwall lining | E108: OP-0120 | Attaching centerstay /window pkt over backwall lining | F108: LPD12068 | G108: ASADUL GAIN | H108: LPD12068 | ASADUL GAIN
C109: OP-0121 | D109: Pasting over Right shell | E109: OP-0121 | Pasting over Right shell | F109: LPDS95282 | G109: ASEENA M | H109: LPDS95282 | ASEENA M
C110: OP-0122 | D110: Pasting over Left Window Center stay pkt | E110: OP-0122 | Pasting over Left Window Center stay pkt | F110: LPD12283 | G110: ASHIK ALI MOLLA | H110: LPD12283 | ASHIK ALI MOLLA
C111: OP-0123 | D111: Attaching left center pkt with right shell | E111: OP-0123 | Attaching left center pkt with right shell | F111: LPDS95711 | G111: ASIFA BANU | H111: LPDS95711 | ASIFA BANU
C112: OP-0124 | D112: Stitching top side of cc pkt &bottom centerstay | E112: OP-0124 | Stitching top side of cc pkt &bottom centerstay | F112: LPD12275 | G112: AYABUL MOLLA | H112: LPD12275 | AYABUL MOLLA
...
